<?xml version="1.0"?>
<robot name="justina" xmlns:xacro="http://www.ros.org/wiki/xacro">
	<xacro:include filename="$(find knowledge)/hardware/justina.gazebo" />
	<!-- Import Rviz colors -->
	<xacro:include filename="$(find knowledge)/hardware/materials.xacro" />
	<xacro:include filename="$(find knowledge)/hardware/macros.xacro" />

	<xacro:property name="base_radius" value="0.21"/>
	<xacro:property name="base_height" value="0.2156"/>
	<xacro:property name="base_mass" value="2.0"/>
	<xacro:property name="wheel_radius" value="0.075"/>
	<xacro:property name="wheel_height" value="0.04"/>
	<xacro:property name="wheel_mass" value="0.52098"/>

	<link name="base_link"/>

	<joint name="hex_base_connect" type="fixed">
		<origin xyz="0 0 0" rpy="0 0 0" />
		<parent link="base_link"/>
		<child link="hex_base_link" />
	</joint>

	<link name="hex_base_link">
		<visual>
			<origin xyz="0.0 0.0 0.075" rpy="0.0 0 1.5708"/>
			<!-- origin xyz="0 0 0.1828" rpy="0 0 0"/ -->
			<geometry> 
				<mesh filename="package://knowledge/hardware/stl/base/baseHex.dae"/>
				<!-- cylinder length="${base_height}" radius="${base_radius}"/ -->
			</geometry>
			<material name="grey"/>
		</visual>
		<collision>
			<origin xyz="0 0 0.1828" rpy="0 0 0"/>
			<geometry><cylinder length="${base_height}" radius="${base_radius}"/></geometry>
		</collision>
		<inertial>
			<origin xyz="0 0 0.1828" rpy="0 0 0"/>
			<mass value="${base_mass}"/>
			<cylinder_inertia m="${base_mass}" r="${base_radius}" h="${base_height}"/>
		</inertial>
	</link>
	<joint name="wheel_front_left_connect" type="continuous">
		<origin xyz="0.1091 0.189 0.075" rpy="1.57078 0 -3.67"/>
		<parent link="hex_base_link"/>
		<child link="wheel_front_left"/>
		<axis xyz="0 0 1"/>
	</joint>

	<link name="wheel_front_left">
		<visual>
			<origin xyz="0 0 0" rpy="0 3.1416 0"/>
			<geometry>
				<mesh filename="package://knowledge/hardware/stl/base/rueda.dae"/>
				<!-- cylinder length="${wheel_height}" radius="${wheel_radius}"/ -->
			</geometry>
			<material name="grey"/>
		</visual>
		<collision>
			<origin xyz="0 0 0" rpy="0 0 0"/>
			<geometry><cylinder length="${wheel_height}" radius="${wheel_radius}"/></geometry>
		</collision>
		<inertial>
			<origin xyz="0 0 0"/>
			<mass value="${wheel_mass}"/>
			<cylinder_inertia m="${wheel_mass}" r="${wheel_radius}" h="${wheel_height}"/>
		</inertial>
	</link>

	<joint name="wheel_back_connect" type="continuous">
		<origin xyz="-0.2182 0 0.075" rpy="1.57078 0 -1.5708"/>
		<parent link="hex_base_link"/>		
		<child link="wheel_back"/>
		<axis xyz="0 0 1"/>
	</joint>

	<link name="wheel_back">
		<visual>
			<origin xyz="0 0 0" rpy="0 3.1416 0"/>
			<geometry>
				<mesh filename="package://knowledge/hardware/stl/base/rueda.dae"/>
				<!-- cylinder length="${wheel_height}" radius="${wheel_radius}"/ -->
			</geometry>
			<material name="grey"/>
		</visual>
		<collision>
			<origin xyz="0 0 0" rpy="0 0 0"/>
			<geometry><cylinder length="${wheel_height}" radius="${wheel_radius}"/></geometry>
		</collision>
		<inertial>
			<origin xyz="0 0 0" rpy="0 0 0"/>
			<mass value="${wheel_mass}"/>
			<cylinder_inertia m="${wheel_mass}" r="${wheel_radius}" h="${wheel_height}"/>
		</inertial>
	</link>

	<joint name="wheel_front_right_connect" type="continuous">
		<origin xyz="0.1091 -0.189 0.075" rpy="1.57078 0 3.67"/>
		<parent link="hex_base_link"/>
		<child link="wheel_front_right"/>
		<axis xyz="0 0 1"/>
	</joint>

	<link name="wheel_front_right">
		<visual>
			<origin xyz="0 0 0" rpy="0 0 0"/>
			<geometry>
				<mesh filename="package://knowledge/hardware/stl/base/rueda.dae"/>
				<!-- cylinder length="${wheel_height}" radius="${wheel_radius}"/ -->
			</geometry>
			<material name="grey"/>
		</visual>
		<collision>
			<origin xyz="0 0 0" rpy="0 0 0"/>
			<geometry><cylinder length="${wheel_height}" radius="${wheel_radius}"/></geometry>
		</collision>
		<inertial>
			<origin xyz="0 0 0" rpy="0 0 0"/>
			<mass value="${wheel_mass}"/>
			<cylinder_inertia m="${wheel_mass}" r="${wheel_radius}" h="${wheel_height}"/>
		</inertial>
	</link>

	<joint name="laser_connect" type="fixed">
		<origin xyz="0.187 0 0.3276" />
		<parent link="hex_base_link"/>
		<child link="laser_link"/>
	</joint>

	<link name="laser_link">
		<collision>
			<origin xyz="0 0 0" rpy="0 0 0"/>
			<geometry>
				<box size="0.08 0.08 0.095"/>
			</geometry>
		</collision>
		<visual>
			<origin xyz="0 0 0" rpy="0 0 0"/>
			<geometry>
				<mesh filename="package://knowledge/hardware/stl/hokuyo.dae"/>
			</geometry>
		</visual>
		<inertial>
			<mass value="0.01"/>
			<origin xyz="0 0 0" rpy="0 0 0"/>
			<box_inertia m="0.01" x="0.08" y="0.08" z="0.095"/>
		</inertial>
	</link>
</robot>