<?xml version="1.0" encoding="utf-8"?>
<!-- =================================================================================== -->
<!-- |    This document was autogenerated by xacro from miztli.xacro                   | -->
<!-- |    EDITING THIS FILE BY HAND IS NOT RECOMMENDED                                 | -->
<!-- =================================================================================== -->
<robot name="justina">
  <gazebo reference="octo_base_link">
    <material>Gazebo/blue</material>
  </gazebo>
  <gazebo reference="wheel_left">
    <material>Gazebo/Black</material>
  </gazebo>
  <gazebo reference="wheel_right">
    <material>Gazebo/Black</material>
  </gazebo>
  <gazebo reference="wheel_front">
    <material>Gazebo/Black</material>
  </gazebo>
  <gazebo reference="wheel_back">
    <material>Gazebo/Black</material>
  </gazebo>
  <gazebo>
    <plugin filename="libgazebo_ros_control.so" name="gazebo_ros_control">
      <robotNamespace>/justina</robotNamespace>
    </plugin>
  </gazebo>
  <gazebo>
    <plugin filename="libgazebo_ros_diff_drive.so" name="differential_drive_controller">
      <legacyMode>false</legacyMode>
      <alwaysOn>true</alwaysOn>
      <updateRate>100</updateRate>
      <leftJoint>wheel_front_left_connect</leftJoint>
      <rightJoint>wheel_front_right_connect</rightJoint>
      <wheelSeparation>0.46</wheelSeparation>
      <wheelDiameter>0.12</wheelDiameter>
      <torque>20</torque>
      <commandTopic>justina/cmd_vel</commandTopic>
      <odometryTopic>justina/odom_diffdrive</odometryTopic>
      <odometryFrame>odom</odometryFrame>
      <robotBaseFrame>base_link</robotBaseFrame>
    </plugin>
  </gazebo>
  <!-- gazebo>
		<plugin name="skid_steer_drive_controller" filename="libgazebo_ros_skid_steer_drive.so">
			<updateRate>100.0</updateRate>
			<robotNamespace>/justina</robotNamespace>
			<leftFrontJoint>wheel_front_left_connect</leftFrontJoint>
			<rightFrontJoint>wheel_front_right_connect</rightFrontJoint>
			<leftRearJoint>wheel_back_left_connect</leftRearJoint>
			<rightRearJoint>wheel_back_right_connect</rightRearJoint>
			<wheelSeparation>0.323</wheelSeparation>
			<wheelDiameter>0.15</wheelDiameter>
			<robotBaseFrame>base_link</robotBaseFrame>
			<torque>20</torque>
			<topicName>cmd_vel</topicName>
			<broadcastTF>false</broadcastTF>
		</plugin>
	</gazebo -->
  <gazebo reference="laser_link">
    <sensor name="head_hokuyo_sensor" type="gpu_ray">
      <pose>0 0 0 0 0 0</pose>
      <visualize>false</visualize>
      <update_rate>40</update_rate>
      <ray>
        <scan>
          <horizontal>
            <samples>720</samples>
            <resolution>1</resolution>
            <min_angle>-1.570796</min_angle>
            <max_angle>1.570796</max_angle>
          </horizontal>
        </scan>
        <range>
          <min>0.10</min>
          <max>30.0</max>
          <resolution>0.01</resolution>
        </range>
        <noise>
          <type>gaussian</type>
          <mean>0.0</mean>
          <stddev>0.01</stddev>
        </noise>
      </ray>
      <plugin filename="libgazebo_ros_gpu_laser.so" name="gazebo_ros_head_hokuyo_controller">
        <topicName>/rrbot/laser/scan</topicName>
        <frameName>laser_link</frameName>
      </plugin>
    </sensor>
  </gazebo>
  <material name="black">
    <color rgba="0.0 0.0 0.0 1.0"/>
  </material>
  <material name="blue">
    <color rgba="0.0 0.0 0.8 1.0"/>
  </material>
  <material name="green">
    <color rgba="0.0 0.8 0.0 1.0"/>
  </material>
  <material name="grey">
    <color rgba="0.2 0.2 0.2 1.0"/>
  </material>
  <material name="orange">
    <color rgba="1.0 0.423529411765 0.0392156862745 1.0"/>
  </material>
  <material name="brown">
    <color rgba="0.870588235294 0.811764705882 0.764705882353 1.0"/>
  </material>
  <material name="red">
    <color rgba="0.8 0.0 0.0 1.0"/>
  </material>
  <material name="white">
    <color rgba="1.0 1.0 1.0 1.0"/>
  </material>
  <link name="base_link"/>
  <joint name="hex_base_connect" type="fixed">
    <origin rpy="0 0 0" xyz="0 0 0"/>
    <parent link="base_link"/>
    <child link="hex_base_link"/>
  </joint>
  <link name="hex_base_link">
    <visual>
      <origin rpy="0.0 0 1.5708" xyz="0.0 0.0 0.075"/>
      <!-- origin xyz="0 0 0.1828" rpy="0 0 0"/ -->
      <geometry>
        <mesh filename="package://knowledge/hardware/stl/base/baseHex.dae"/>
        <!-- cylinder length="${base_height}" radius="${base_radius}"/ -->
      </geometry>
      <material name="grey"/>
    </visual>
    <collision>
      <origin rpy="0 0 0" xyz="0 0 0.1828"/>
      <geometry>
        <cylinder length="0.2156" radius="0.21"/>
      </geometry>
    </collision>
    <inertial>
      <origin rpy="0 0 0" xyz="0 0 0.1828"/>
      <mass value="2.0"/>
      <inertia ixx="0.0297972266667" ixy="0" ixz="0" iyy="0.0297972266667" iyz="0" izz="0.0441"/>
    </inertial>
  </link>
  <joint name="wheel_front_left_connect" type="continuous">
    <origin rpy="1.57078 0 -3.67" xyz="0.1091 0.189 0.075"/>
    <parent link="hex_base_link"/>
    <child link="wheel_front_left"/>
    <axis xyz="0 0 1"/>
  </joint>
  <link name="wheel_front_left">
    <visual>
      <origin rpy="0 3.1416 0" xyz="0 0 0"/>
      <geometry>
        <mesh filename="package://knowledge/hardware/stl/base/rueda.dae"/>
        <!-- cylinder length="${wheel_height}" radius="${wheel_radius}"/ -->
      </geometry>
      <material name="grey"/>
    </visual>
    <collision>
      <origin rpy="0 0 0" xyz="0 0 0"/>
      <geometry>
        <cylinder length="0.04" radius="0.075"/>
      </geometry>
    </collision>
    <inertial>
      <origin xyz="0 0 0"/>
      <mass value="0.52098"/>
      <inertia ixx="0.000802092125" ixy="0" ixz="0" iyy="0.000802092125" iyz="0" izz="0.00146525625"/>
    </inertial>
  </link>
  <joint name="wheel_back_connect" type="continuous">
    <origin rpy="1.57078 0 -1.5708" xyz="-0.2182 0 0.075"/>
    <parent link="hex_base_link"/>
    <child link="wheel_back"/>
    <axis xyz="0 0 1"/>
  </joint>
  <link name="wheel_back">
    <visual>
      <origin rpy="0 3.1416 0" xyz="0 0 0"/>
      <geometry>
        <mesh filename="package://knowledge/hardware/stl/base/rueda.dae"/>
        <!-- cylinder length="${wheel_height}" radius="${wheel_radius}"/ -->
      </geometry>
      <material name="grey"/>
    </visual>
    <collision>
      <origin rpy="0 0 0" xyz="0 0 0"/>
      <geometry>
        <cylinder length="0.04" radius="0.075"/>
      </geometry>
    </collision>
    <inertial>
      <origin rpy="0 0 0" xyz="0 0 0"/>
      <mass value="0.52098"/>
      <inertia ixx="0.000802092125" ixy="0" ixz="0" iyy="0.000802092125" iyz="0" izz="0.00146525625"/>
    </inertial>
  </link>
  <joint name="wheel_front_right_connect" type="continuous">
    <origin rpy="1.57078 0 3.67" xyz="0.1091 -0.189 0.075"/>
    <parent link="hex_base_link"/>
    <child link="wheel_front_right"/>
    <axis xyz="0 0 1"/>
  </joint>
  <link name="wheel_front_right">
    <visual>
      <origin rpy="0 0 0" xyz="0 0 0"/>
      <geometry>
        <mesh filename="package://knowledge/hardware/stl/base/rueda.dae"/>
        <!-- cylinder length="${wheel_height}" radius="${wheel_radius}"/ -->
      </geometry>
      <material name="grey"/>
    </visual>
    <collision>
      <origin rpy="0 0 0" xyz="0 0 0"/>
      <geometry>
        <cylinder length="0.04" radius="0.075"/>
      </geometry>
    </collision>
    <inertial>
      <origin rpy="0 0 0" xyz="0 0 0"/>
      <mass value="0.52098"/>
      <inertia ixx="0.000802092125" ixy="0" ixz="0" iyy="0.000802092125" iyz="0" izz="0.00146525625"/>
    </inertial>
  </link>
  <joint name="laser_connect" type="fixed">
    <origin xyz="0.187 0 0.3276"/>
    <parent link="hex_base_link"/>
    <child link="laser"/>
  </joint>
  <link name="laser">
    <collision>
      <origin rpy="0 0 0" xyz="0 0 0"/>
      <geometry>
        <box size="0.08 0.08 0.095"/>
      </geometry>
    </collision>
    <visual>
      <origin rpy="0 0 0" xyz="0 0 0"/>
      <geometry>
        <mesh filename="package://knowledge/hardware/stl/hokuyo.dae"/>
      </geometry>
    </visual>
    <inertial>
      <mass value="0.01"/>
      <origin rpy="0 0 0" xyz="0 0 0"/>
      <inertia ixx="1.28541666667e-05" ixy="0" ixz="0" iyy="1.28541666667e-05" iyz="0" izz="1.28541666667e-05"/>
    </inertial>
  </link>
  <!--
 #################################
	wheels links and Joint
  ################################
    -->
  <transmission name="tran1">
    <type>transmission_interface/SimpleTransmission</type>
    <joint name="wheel_front_left_connect">
      <hardwareInterface>hardware_interface/EffortJointInterface</hardwareInterface>
    </joint>
    <actuator name="motor1">
      <hardwareInterface>hardware_interface/EffortJointInterface</hardwareInterface>
      <mechanicalReduction>16</mechanicalReduction>
    </actuator>
  </transmission>
  <transmission name="tran2">
    <type>transmission_interface/SimpleTransmission</type>
    <joint name="wheel_back_left_connect">
      <hardwareInterface>hardware_interface/EffortJointInterface</hardwareInterface>
    </joint>
    <actuator name="motor2">
      <hardwareInterface>hardware_interface/EffortJointInterface</hardwareInterface>
      <mechanicalReduction>16</mechanicalReduction>
    </actuator>
  </transmission>
  <transmission name="tran3">
    <type>transmission_interface/SimpleTransmission</type>
    <joint name="wheel_back_right_connect">
      <hardwareInterface>hardware_interface/EffortJointInterface</hardwareInterface>
    </joint>
    <actuator name="motor3">
      <hardwareInterface>hardware_interface/EffortJointInterface</hardwareInterface>
      <mechanicalReduction>16</mechanicalReduction>
    </actuator>
  </transmission>
  <transmission name="tran4">
    <type>transmission_interface/SimpleTransmission</type>
    <joint name="wheel_front_right_connect">
      <hardwareInterface>hardware_interface/EffortJointInterface</hardwareInterface>
    </joint>
    <actuator name="motor4">
      <hardwareInterface>hardware_interface/EffortJointInterface</hardwareInterface>
      <mechanicalReduction>16</mechanicalReduction>
    </actuator>
  </transmission>
</robot>

